[2025-04-01 07:18:00,229] [INFO] [logger:__init__:77] - Logger initialized. Log directory: C:\Users\mecha\Documents\lhydra-hybrid\logs
[2025-04-01 07:18:00,229] [INFO] [generate_recommendations_v2:main:402] - ================================================================================
[2025-04-01 07:18:00,229] [INFO] [generate_recommendations_v2:main:403] - Starting recommendation generation at 20250401_071800
[2025-04-01 07:18:00,244] [INFO] [generate_recommendations_v2:main:404] - ================================================================================
[2025-04-01 07:18:00,244] [INFO] [generate_recommendations_v2:main:414] - Using device: cpu
[2025-04-01 07:18:00,244] [INFO] [generate_recommendations_v2:from_checkpoint:354] - Loading model from models/checkpoints/best_model.pt
[2025-04-01 07:18:00,244] [INFO] [generate_recommendations_v2:from_checkpoint:358] - Loading user features from data/preprocessed/user_features.csv
[2025-04-01 07:18:00,244] [ERROR] [generate_recommendations_v2:main:434] - Error initializing recommendation engine: [Errno 2] No such file or directory: 'data/preprocessed/user_features.csv'
Traceback (most recent call last):
  File "C:\Users\mecha\Documents\lhydra-hybrid\scripts\generate_recommendations_v2.py", line 424, in main
    engine = RecommendationEngine.from_checkpoint(
  File "C:\Users\mecha\Documents\lhydra-hybrid\scripts\generate_recommendations_v2.py", line 359, in from_checkpoint
    user_features = pd.read_csv(user_features_path)
  File "C:\Users\mecha\anaconda3\envs\sophia-dl\lib\site-packages\pandas\io\parsers\readers.py", line 1026, in read_csv
    return _read(filepath_or_buffer, kwds)
  File "C:\Users\mecha\anaconda3\envs\sophia-dl\lib\site-packages\pandas\io\parsers\readers.py", line 620, in _read
    parser = TextFileReader(filepath_or_buffer, **kwds)
  File "C:\Users\mecha\anaconda3\envs\sophia-dl\lib\site-packages\pandas\io\parsers\readers.py", line 1620, in __init__
    self._engine = self._make_engine(f, self.engine)
  File "C:\Users\mecha\anaconda3\envs\sophia-dl\lib\site-packages\pandas\io\parsers\readers.py", line 1880, in _make_engine
    self.handles = get_handle(
  File "C:\Users\mecha\anaconda3\envs\sophia-dl\lib\site-packages\pandas\io\common.py", line 873, in get_handle
    handle = open(
FileNotFoundError: [Errno 2] No such file or directory: 'data/preprocessed/user_features.csv'
